Workbook
Name Print_Area: ИНВОЙС!$A$1:$H$44
Name Print_Area: СМАПП!$A$2:$Q$22

Sheet СМАПП
B1: CMR № | D1: =VLOOKUP(D7,'Получатель и перевозчик'!A:G,7,FALSE)& RIGHT(YEAR(TODAY()), 2)& DAY(TODAY())&"-"&MID(D11, 2, 3) -> RA263-209 | E1: =TODAY() -> 46025 | F1: Формируется автоматически
B2: Инвойс № | D2: CI-20102025-001 | E2: 45951 | F2: вносим сами
B3: Номер контракта | D3: =VLOOKUP(D7,'Получатель и перевозчик'!A:F, 5, FALSE) -> RA-25/2110-CH | E3: =VLOOKUP(D7,'Получатель и перевозчик'!A:F, 6, FALSE) -> 45951
B4: Условия поставки | D4: / DAP-СУЙФЭНЬХЭ /
B5: Отправитель | D5: YANTAI SUNDY SCIENCE ENVIROMENTAL TECHNOLOGY LTD.
B6: Адрес отправителя | D6: =VLOOKUP(D5,Отправитель!A:B, 2, FALSE) -> BUILDING 8，NO.39, SCIENCE AND TECHNOLOGY AVENUE, YANTAI HIGH-TECH ZONE, CHINA
B7: Получатель: | D7: ООО "РЕГИОНАЛЬНАЯ ТОРГОВАЯ КОМПАНИЯ "РОСАКВА" | E7: =VLOOKUP(D7,'Получатель и перевозчик'!A:D, 3, FALSE) -> ИНН 7810846669 | F7: =VLOOKUP(D7,'Получатель и перевозчик'!A:D,4, FALSE) -> ОГРН 1117847475987
B8: Адрес получателя | D8: =VLOOKUP(D7,'Получатель и перевозчик'!A:D, 2, FALSE) -> 197374, г.Санкт-Петербург, вн.тер.г. муниципальный округ № 65, ул. Мебельная, д. 5, литера а, помещ. 1-н
B9: Продавец | D9: YANTAI SUNDY SCIENCE ENVIROMENTAL TECHNOLOGY LTD.
B10: Адрес отправителя | D10: =VLOOKUP(D9,Отправитель!A:B, 2, FALSE) -> BUILDING 8，NO.39, SCIENCE AND TECHNOLOGY AVENUE, YANTAI HIGH-TECH ZONE, CHINA
B11: А/М | D11: М209АУ125
B12: П/П | D12: =VLOOKUP(D11,'доп данные'!D:G, 2, FALSE) -> АВ994425 | E12: =VLOOKUP(D11,'доп данные'!D:G, 4, FALSE) -> 10716050-25/2019 | F12: <---------- | G12: Свидетельство о допуске
B13: VIN | D13: =VLOOKUP(D11,'доп данные'!D:G, 3, FALSE) -> XLRTE47MS0E962123
B14: Водитель | D14: Шевченко Сергей Дмитриевич
B15: Паспорт | D15: =VLOOKUP(D14,'доп данные'!I:K, 2, FALSE) -> 77-2950046 | E15: =VLOOKUP(D14,'доп данные'!I:K, 3, FALSE) -> 45378 | F15: <--Дата выдачи
B16: Перевозчик | D16: ООО «РЕАЛ ЭСТЕЙТ КОМПАНИ»
B17: Адрес | D17: =VLOOKUP(D16,'Получатель и перевозчик'!I:L, 2, FALSE) -> Приморский край, г. Владивосток, ул. Запорожская д.77, оф.720 | E17: =VLOOKUP(D16,'Получатель и перевозчик'!I:L, 3, FALSE) -> ИНН 2538144525 | F17: =VLOOKUP(D16,'Получатель и перевозчик'!I:L, 4, FALSE) -> ОГРН 1112538000706
B18: Пост прибытия | D18: т/п Уссурийский | E18: 10716050
B19: Дата ожид прибытия | D19: =TODAY()+1 -> 46026
B20: Дата составления накладной | D20: =TODAY() -> 46025
A22: номер в инвойсе | B22: код ТНВЭД | C22: цена в гтд , юани | D22: наименование груза | E22: изготовитель | F22: адрес изготовителя | G22: торговая марка | H22: модель | I22: маркировка грузового места/序号 | J22: род упаковки | K22: кол - во мест | L22: еденица измерения | M22: кол-во товара | N22: вес брутто | O22: вес нетто | P22: обьем | Q22: материал | T22: кол - во мест | U22: мест частично
A23: 1 | B23: 8514390000 | C23: 250000 | D23: ИСПЫТАТЕЛЬНАЯ КОКСОВАЯ ПЕЧЬ | E23: Zhongwei National Engineering Research Center For Coking Technology Co.,Ltd. | G23: НЕ ОБОЗНАЧЕНА | H23: отсутствует | I23: В292-1-3 | J23: фанер.ящик | K23: 3 | L23: компл. | M23: 1 | N23: 1096 | O23: 908.8
A24: 2 | B24: 8419908509 | C24: 64000 | D24: Реторта коксования угля | E24: YANTAI SUNDY SCIENCE ENVIROMENTAL TECHNOLOGY LТD | G24: НЕ ОБОЗНАЧЕНА | H24: отсутствует | I24: В292-4 | J24: фанер.ящик | K24: 1 | L24: компл. | M24: 2 | N24: 52.8 | O24: 35
A25: 3 | B25: 6903909000 | C25: 14000 | D25: Теплоизоляционный кожух реторты коксования угля | E25: YANTAI SUNDY SCIENCE ENVIROMENTAL TECHNOLOGY LТD | G25: НЕ ОБОЗНАЧЕНА | H25: отсутствует | I25: В292-4 | J25: фанер.ящик | K25: часть места | L25: компл. | M25: 1 | N25: 15 | O25: 10
A26: 4 | B26: 6903909000 | C26: 1760 | D26: Теплоизоляционная накладка | E26: YANTAI SUNDY SCIENCE ENVIROMENTAL TECHNOLOGY LТD | G26: НЕ ОБОЗНАЧЕНА | H26: отсутствует | I26: В292-4 | J26: фанер.ящик | K26: часть места | L26: шт | M26: 6 | N26: 3 | O26: 2.4
A27: 5 | B27: 9025192000 | C27: 10300 | D27: Термопара HCHS2KG-5-3 | E27: Zhongwei National Engineering Research Center For Coking Technology Co.,Ltd. | G27: НЕ ОБОЗНАЧЕНА | H27: отсутствует | I27: В292-4 | J27: фанер.ящик | K27: часть места | L27: шт | M27: 2 | N27: 2 | O27: 1.1
A28: 6 | B28: 7326909807 | C28: 900 | D28: Прокладка реторты коксования | E28: YANTAI SUNDY SCIENCE ENVIROMENTAL TECHNOLOGY LТD | G28: НЕ ОБОЗНАЧЕНА | H28: отсутствует | I28: В292-4 | J28: фанер.ящик | K28: часть места | L28: шт | M28: 20 | N28: 3 | O28: 2
A29: 7 | B29: 7326909807 | C29: 200 | D29: Уплотнительная прокладка | E29: YANTAI SUNDY SCIENCE ENVIROMENTAL TECHNOLOGY LТD | G29: НЕ ОБОЗНАЧЕНА | H29: отсутствует | I29: В292-4 | J29: фанер.ящик | K29: часть места | L29: шт | M29: 20 | N29: 1.5 | O29: 0.9
A30: 8 | B30: 3926909709 | C30: 60 | D30: Уплотнительная прокладка из ПТФЭ | E30: YANTAI SUNDY SCIENCE ENVIROMENTAL TECHNOLOGY LТD | G30: НЕ ОБОЗНАЧЕНА | H30: отсутствует | I30: В292-4 | J30: фанер.ящик | K30: часть места | L30: шт | M30: 10 | N30: 0.3 | O30: 0.2

Sheet СПЕЦ
A1: отгрузочная спецификация № | D1: =CONCATENATE("С","-",СМАПП!D1) -> С-RA263-209
A2: ПРОДАВЕЦ | C2: =CONCATENATE(СМАПП!D9,", ",СМАПП!D10) -> YANTAI SUNDY SCIENCE ENVIROMENTAL TECHNOLOGY LTD., BUILDING 8，NO.39, SCIENCE AND TECHNOLOGY AVENUE, YANTAI HIGH-TECH ZONE, CHINA
A3: ОТПРАВИТЕЛЬ | C3: =CONCATENATE(СМАПП!D5,", ",СМАПП!D6) -> YANTAI SUNDY SCIENCE ENVIROMENTAL TECHNOLOGY LTD., BUILDING 8，NO.39, SCIENCE AND TECHNOLOGY AVENUE, YANTAI HIGH-TECH ZONE, CHINA | L3: ТРАНСПОРТ
A4: ПОЛУЧАТЕЛЬ | C4: =CONCATENATE(СМАПП!D7,", ",СМАПП!D8) -> ООО "РЕГИОНАЛЬНАЯ ТОРГОВАЯ КОМПАНИЯ "РОСАКВА", 197374, г.Санкт-Петербург, вн.тер.г. муниципальный округ № 65, ул. Мебельная, д. 5, литера а, помещ. 1-н | E4: =СМАПП!E7 -> ИНН 7810846669 | G4: =СМАПП!F7 -> ОГРН 1117847475987 | L4: ="А/М "&СМАПП!D11&" П/П "&СМАПП!D12 -> А/М М209АУ125 П/П АВ994425
A5: КОНТРАКТ | C5: =CONCATENATE(СМАПП!D3," от ",TEXT(СМАПП!E3, "ДД.ММ.ГГГГ")) -> RA-25/2110-CH от 21.10.2025 | E5: =СМАПП!D4 -> / DAP-СУЙФЭНЬХЭ / | L5: =СМАПП!D13 -> XLRTE47MS0E962123
A7: МЕСТО | C7: СВХ ООО "НАБАЗ" , ПРИМОРСКИЙ КРАЙ, Г. УССУРИЙСК,УЛ. ЛИМИЧЕВСКАЯ,21-А | L7: свидетельство о допущении
A8: РАЗГРУЗКИ | C8: 10716/291110/10032/11 действует с 08.10.2025 г. | L8: =СМАПП!E12 -> 10716050-25/2019
A10: ПЕРЕВОЗЧИК | C10: =CONCATENATE(СМАПП!D16,", ",СМАПП!D17) -> ООО «РЕАЛ ЭСТЕЙТ КОМПАНИ», Приморский край, г. Владивосток, ул. Запорожская д.77, оф.720 | L10: водитель | M10: =СМАПП!D14 -> Шевченко Сергей Дмитриевич
C11: =СМАПП!E17 -> ИНН 2538144525 | D11: =СМАПП!F17 -> ОГРН 1112538000706 | L11: паспорт | M11: =СМАПП!D15 -> 77-2950046
A13: № | B13: код | C13: наименование груза | D13: маркировка | E13: род | F13: кол - во | H13: еденица | I13: кол-во | J13: вес | M13: цена | N13: стоимость
A14: п/п | B14: ТНВЭД | D14: грузового места | E14: упаковки | F14: мест | H14: измерения | I14: товара | J14: нетто | L14: брутто | M14: unit price (¥) | N14: CNY
A15: =СМАПП!A23 -> 1 | B15: =СМАПП!B23 -> 8514390000 | C15: =СМАПП!D23&", изгот. : "&СМАПП!E23&",торг. марка: "&СМАПП!G23&", модель: "&СМАПП!H23 -> ИСПЫТАТЕЛЬНАЯ КОКСОВАЯ ПЕЧЬ, изгот. : Zhongwei National Engineering Research Center For Coking Technology Co.,Ltd.,торг. марка: НЕ ОБОЗНАЧЕНА, модель: отсутствует | D15: =СМАПП!I23 -> В292-1-3 | E15: =СМАПП!J23 -> фанер.ящик | F15: =СМАПП!K23 -> 3 | H15: =СМАПП!L23 -> компл. | I15: =СМАПП!M23 -> 1 | J15: =СМАПП!O23 -> 908.8 | K15: =СМАПП!#REF! -> #REF! | L15: =СМАПП!N23 -> 1096 | M15: =N15/I15 -> 250000 | N15: =СМАПП!C23 -> 250000
A16: =СМАПП!A24 -> 2 | B16: =СМАПП!B24 -> 8419908509 | C16: =СМАПП!D24&", изгот. : "&СМАПП!E24&",торг. марка: "&СМАПП!G24&", модель: "&СМАПП!H24 -> Реторта коксования угля, изгот. : YANTAI SUNDY SCIENCE ENVIROMENTAL TECHNOLOGY LТD,торг. марка: НЕ ОБОЗНАЧЕНА, модель: отсутствует | D16: =СМАПП!I24 -> В292-4 | E16: =СМАПП!J24 -> фанер.ящик | F16: =СМАПП!K24 -> 1 | H16: =СМАПП!L24 -> компл. | I16: =СМАПП!M24 -> 2 | J16: =СМАПП!O24 -> 35 | K16: =СМАПП!#REF! -> #REF! | L16: =СМАПП!N24 -> 52.8 | M16: =N16/I16 -> 32000 | N16: =СМАПП!C24 -> 64000
A17: =СМАПП!A25 -> 3 | B17: =СМАПП!B25 -> 6903909000 | C17: =СМАПП!D25&", изгот. : "&СМАПП!E25&",торг. марка: "&СМАПП!G25&", модель: "&СМАПП!H25 -> Теплоизоляционный кожух реторты коксования угля, изгот. : YANTAI SUNDY SCIENCE ENVIROMENTAL TECHNOLOGY LТD,торг. марка: НЕ ОБОЗНАЧЕНА, модель: отсутствует | D17: =СМАПП!I25 -> В292-4 | E17: =СМАПП!J25 -> фанер.ящик | F17: =СМАПП!K25 -> часть места | H17: =СМАПП!L25 -> компл. | I17: =СМАПП!M25 -> 1 | J17: =СМАПП!O25 -> 10 | K17: =СМАПП!#REF! -> #REF! | L17: =СМАПП!N25 -> 15 | M17: =N17/I17 -> 14000 | N17: =СМАПП!C25 -> 14000
A18: =СМАПП!A26 -> 4 | B18: =СМАПП!B26 -> 6903909000 | C18: =СМАПП!D26&", изгот. : "&СМАПП!E26&",торг. марка: "&СМАПП!G26&", модель: "&СМАПП!H26 -> Теплоизоляционная накладка, изгот. : YANTAI SUNDY SCIENCE ENVIROMENTAL TECHNOLOGY LТD,торг. марка: НЕ ОБОЗНАЧЕНА, модель: отсутствует | D18: =СМАПП!I26 -> В292-4 | E18: =СМАПП!J26 -> фанер.ящик | F18: =СМАПП!K26 -> часть места | H18: =СМАПП!L26 -> шт | I18: =СМАПП!M26 -> 6 | J18: =СМАПП!O26 -> 2.4 | K18: =СМАПП!#REF! -> #REF! | L18: =СМАПП!N26 -> 3 | M18: =N18/I18 -> 293.33333 | N18: =СМАПП!C26 -> 1760
A19: =СМАПП!A27 -> 5 | B19: =СМАПП!B27 -> 9025192000 | C19: =СМАПП!D27&", изгот. : "&СМАПП!E27&",торг. марка: "&СМАПП!G27&", модель: "&СМАПП!H27 -> Термопара HCHS2KG-5-3, изгот. : Zhongwei National Engineering Research Center For Coking Technology Co.,Ltd.,торг. марка: НЕ ОБОЗНАЧЕНА, модель: отсутствует | D19: =СМАПП!I27 -> В292-4 | E19: =СМАПП!J27 -> фанер.ящик | F19: =СМАПП!K27 -> часть места | H19: =СМАПП!L27 -> шт | I19: =СМАПП!M27 -> 2 | J19: =СМАПП!O27 -> 1.1 | K19: =СМАПП!#REF! -> #REF! | L19: =СМАПП!N27 -> 2 | M19: =N19/I19 -> 5150 | N19: =СМАПП!C27 -> 10300
A20: =СМАПП!A28 -> 6 | B20: =СМАПП!B28 -> 7326909807 | C20: =СМАПП!D28&", изгот. : "&СМАПП!E28&",торг. марка: "&СМАПП!G28&", модель: "&СМАПП!H28 -> Прокладка реторты коксования, изгот. : YANTAI SUNDY SCIENCE ENVIROMENTAL TECHNOLOGY LТD,торг. марка: НЕ ОБОЗНАЧЕНА, модель: отсутствует | D20: =СМАПП!I28 -> В292-4 | E20: =СМАПП!J28 -> фанер.ящик | F20: =СМАПП!K28 -> часть места | H20: =СМАПП!L28 -> шт | I20: =СМАПП!M28 -> 20 | J20: =СМАПП!O28 -> 2 | K20: =СМАПП!#REF! -> #REF! | L20: =СМАПП!N28 -> 3 | M20: =N20/I20 -> 45 | N20: =СМАПП!C28 -> 900
A21: =СМАПП!A29 -> 7 | B21: =СМАПП!B29 -> 7326909807 | C21: =СМАПП!D29&", изгот. : "&СМАПП!E29&",торг. марка: "&СМАПП!G29&", модель: "&СМАПП!H29 -> Уплотнительная прокладка, изгот. : YANTAI SUNDY SCIENCE ENVIROMENTAL TECHNOLOGY LТD,торг. марка: НЕ ОБОЗНАЧЕНА, модель: отсутствует | D21: =СМАПП!I29 -> В292-4 | E21: =СМАПП!J29 -> фанер.ящик | F21: =СМАПП!K29 -> часть места | H21: =СМАПП!L29 -> шт | I21: =СМАПП!M29 -> 20 | J21: =СМАПП!O29 -> 0.9 | K21: =СМАПП!#REF! -> #REF! | L21: =СМАПП!N29 -> 1.5 | M21: =N21/I21 -> 10 | N21: =СМАПП!C29 -> 200
A22: =СМАПП!A30 -> 8 | B22: =СМАПП!B30 -> 3926909709 | C22: =СМАПП!D30&", изгот. : "&СМАПП!E30&",торг. марка: "&СМАПП!G30&", модель: "&СМАПП!H30 -> Уплотнительная прокладка из ПТФЭ, изгот. : YANTAI SUNDY SCIENCE ENVIROMENTAL TECHNOLOGY LТD,торг. марка: НЕ ОБОЗНАЧЕНА, модель: отсутствует | D22: =СМАПП!I30 -> В292-4 | E22: =СМАПП!J30 -> фанер.ящик | F22: =СМАПП!K30 -> часть места | H22: =СМАПП!L30 -> шт | I22: =СМАПП!M30 -> 10 | J22: =СМАПП!O30 -> 0.2 | K22: =СМАПП!#REF! -> #REF! | L22: =СМАПП!N30 -> 0.3 | M22: =N22/I22 -> 6 | N22: =СМАПП!C30 -> 60
E23: ИТОГО | F23: =SUM(F15:F22) -> 4 | I23: =SUM(I15:I22) -> 62 | J23: =SUM(J15:J22) -> 960.4 | K23: =SUM(K15:K22) -> #REF! | L23: =SUM(L15:L22) -> 1173.6 | N23: =SUM(N15:N22) -> 341220
D25: ТОВАРЫ ПРОИЗВОДСТВА КНР
A26: СОСТАВЛЕНА | C26: =СМАПП!D20 -> 46025

Sheet ИНВОЙС
A2: =СМАПП!D9 -> YANTAI SUNDY SCIENCE ENVIROMENTAL TECHNOLOGY LTD.
A3: =СМАПП!D10 -> BUILDING 8，NO.39, SCIENCE AND TECHNOLOGY AVENUE, YANTAI HIGH-TECH ZONE, CHINA
A5: COMMERCIAL INVOICE
A7: Shipper / exporter : | E7: Invoice NO.and date
A8: =СМАПП!D5 & " "& СМАПП!D6 -> YANTAI SUNDY SCIENCE ENVIROMENTAL TECHNOLOGY LTD. BUILDING 8，NO.39, SCIENCE AND TECHNOLOGY AVENUE, YANTAI HIGH-TECH ZONE, CHINA | F8: =СМАПП!D2 -> CI-20102025-001
F9: =СМАПП!E2 -> 45951
A10: Seller:
A11: =СМАПП!D9&" "&СМАПП!D10 -> YANTAI SUNDY SCIENCE ENVIROMENTAL TECHNOLOGY LTD. BUILDING 8，NO.39, SCIENCE AND TECHNOLOGY AVENUE, YANTAI HIGH-TECH ZONE, CHINA
A13: TO : | E13: Place of Destination
A14: =СМАПП!D7&" "&СМАПП!D8 -> ООО "РЕГИОНАЛЬНАЯ ТОРГОВАЯ КОМПАНИЯ "РОСАКВА" 197374, г.Санкт-Петербург, вн.тер.г. муниципальный округ № 65, ул. Мебельная, д. 5, литера а, помещ. 1-н | E14: =СПЕЦ!C7 -> СВХ ООО "НАБАЗ" , ПРИМОРСКИЙ КРАЙ, Г. УССУРИЙСК,УЛ. ЛИМИЧЕВСКАЯ,21-А
A16: =СМАПП!E7&", "&СМАПП!F7 -> ИНН 7810846669, ОГРН 1117847475987 | E16: =СПЕЦ!C8 -> 10716/291110/10032/11 действует с 08.10.2025 г.
A17: port of loading | B17: final destination | E17: Contract NO. and date
A18: Китай | B18: Россия | E18: =СМАПП!D3 -> RA-25/2110-CH | H18: =СМАПП!E3 -> 45951
E19: =СПЕЦ!E5 -> / DAP-СУЙФЭНЬХЭ /
E20: Means of transport : by truck
F21: =СМАПП!D11 -> М209АУ125
A23: ТОВАРЫ ПРОИЗВОДСТВА КНР
A25: marks | B25: description | C25: quantity | E25: unit price (¥) | G25: amount (¥)
A26: =СПЕЦ!C15 -> ИСПЫТАТЕЛЬНАЯ КОКСОВАЯ ПЕЧЬ, изгот. : Zhongwei National Engineering Research Center For Coking Technology Co.,Ltd.,торг. марка: НЕ ОБОЗНАЧЕНА, модель: отсутствует | B26: =LEFT(СПЕЦ!B15,4) -> 8514 | C26: PCS | D26: =СПЕЦ!I15 -> 1 | E26: =G26/D26 -> 250000 | G26: =СПЕЦ!N15 -> 250000 | H26: ¥
A27: =СПЕЦ!C16 -> Реторта коксования угля, изгот. : YANTAI SUNDY SCIENCE ENVIROMENTAL TECHNOLOGY LТD,торг. марка: НЕ ОБОЗНАЧЕНА, модель: отсутствует | B27: =LEFT(СПЕЦ!B16,4) -> 8419 | C27: PCS | D27: =СПЕЦ!I16 -> 2 | E27: =G27/D27 -> 32000 | G27: =СПЕЦ!N16 -> 64000 | H27: ¥
A28: =СПЕЦ!C17 -> Теплоизоляционный кожух реторты коксования угля, изгот. : YANTAI SUNDY SCIENCE ENVIROMENTAL TECHNOLOGY LТD,торг. марка: НЕ ОБОЗНАЧЕНА, модель: отсутствует | B28: =LEFT(СПЕЦ!B17,4) -> 6903 | C28: PCS | D28: =СПЕЦ!I17 -> 1 | E28: =G28/D28 -> 14000 | G28: =СПЕЦ!N17 -> 14000 | H28: ¥
A29: =СПЕЦ!C18 -> Теплоизоляционная накладка, изгот. : YANTAI SUNDY SCIENCE ENVIROMENTAL TECHNOLOGY LТD,торг. марка: НЕ ОБОЗНАЧЕНА, модель: отсутствует | B29: =LEFT(СПЕЦ!B18,4) -> 6903 | C29: PCS | D29: =СПЕЦ!I18 -> 6 | E29: =G29/D29 -> 293.33333 | G29: =СПЕЦ!N18 -> 1760 | H29: ¥
A30: =СПЕЦ!C19 -> Термопара HCHS2KG-5-3, изгот. : Zhongwei National Engineering Research Center For Coking Technology Co.,Ltd.,торг. марка: НЕ ОБОЗНАЧЕНА, модель: отсутствует | B30: =LEFT(СПЕЦ!B19,4) -> 9025 | C30: PCS | D30: =СПЕЦ!I19 -> 2 | E30: =G30/D30 -> 5150 | G30: =СПЕЦ!N19 -> 10300 | H30: ¥
A31: =СПЕЦ!C20 -> Прокладка реторты коксования, изгот. : YANTAI SUNDY SCIENCE ENVIROMENTAL TECHNOLOGY LТD,торг. марка: НЕ ОБОЗНАЧЕНА, модель: отсутствует | B31: =LEFT(СПЕЦ!B20,4) -> 7326 | C31: PCS | D31: =СПЕЦ!I20 -> 20 | E31: =G31/D31 -> 45 | G31: =СПЕЦ!N20 -> 900 | H31: ¥
A32: =СПЕЦ!C21 -> Уплотнительная прокладка, изгот. : YANTAI SUNDY SCIENCE ENVIROMENTAL TECHNOLOGY LТD,торг. марка: НЕ ОБОЗНАЧЕНА, модель: отсутствует | B32: =LEFT(СПЕЦ!B21,4) -> 7326 | C32: PCS | D32: =СПЕЦ!I21 -> 20 | E32: =G32/D32 -> 10 | G32: =СПЕЦ!N21 -> 200 | H32: ¥
A33: =СПЕЦ!C22 -> Уплотнительная прокладка из ПТФЭ, изгот. : YANTAI SUNDY SCIENCE ENVIROMENTAL TECHNOLOGY LТD,торг. марка: НЕ ОБОЗНАЧЕНА, модель: отсутствует | B33: =LEFT(СПЕЦ!B22,4) -> 3926 | C33: PCS | D33: =СПЕЦ!I22 -> 10 | E33: =G33/D33 -> 6 | G33: =СПЕЦ!N22 -> 60 | H33: ¥
B36: TOTAL : | D36: =SUM(D26:D35) -> 62 | G36: =SUM(G26:G35) -> 341220 | H36: CNY
B40: Итого : | C40: =G36 -> 341220 | E40: CNY(кит.юаней)

Sheet CMR1
B1: 1 | C1: Отправитель (наименование, адрес, страна) | AE1: =СМАПП!D1 -> RA263-209 | AL1: При перевозке опасного груза указывать кроме возможного разрешения класс, цифру, а также, в случае необходимости букву опасного груза.
B2: =СМАПП!D5&" "&СМАПП!D6 -> YANTAI SUNDY SCIENCE ENVIROMENTAL TECHNOLOGY LTD. BUILDING 8，NO.39, SCIENCE AND TECHNOLOGY AVENUE, YANTAI HIGH-TECH ZONE, CHINA
T4: Международная товарно-транспортная накладная
T5: Данная перевозка, несмотря ни накакие прочие договоры, осуществляется в соответсвии с условиями Конвенции о договоре международной дорожной перевозке грузов (КДПГ)
B7: 2 | C7: Получатель (наименование, адрес, страна) | T7: 16 | U7: Перевозчик (наименование, адрес, страна)
B8: =СМАПП!D7&" "&СМАПП!D8 -> ООО "РЕГИОНАЛЬНАЯ ТОРГОВАЯ КОМПАНИЯ "РОСАКВА" 197374, г.Санкт-Петербург, вн.тер.г. муниципальный округ № 65, ул. Мебельная, д. 5, литера а, помещ. 1-н | T8: =СМАПП!D16&" "&СМАПП!D17 -> ООО «РЕАЛ ЭСТЕЙТ КОМПАНИ» Приморский край, г. Владивосток, ул. Запорожская д.77, оф.720
B10: РОССИЯ | T10: РОССИЯ
B11: =СМАПП!E7 -> ИНН 7810846669 | T11: =СМАПП!E17 -> ИНН 2538144525
B12: =СМАПП!F7 -> ОГРН 1117847475987 | T12: =СМАПП!F17 -> ОГРН 1112538000706
A13: Позиции, выделенные рамкой заполняются перевозчиком | B13: 3 | C13: Место разгрузки груза | T13: 17 | U13: Последующий перевозчик (наименование, адрес, страна)
B14: Место | D14: =СПЕЦ!C7 -> СВХ ООО "НАБАЗ" , ПРИМОРСКИЙ КРАЙ, Г. УССУРИЙСК,УЛ. ЛИМИЧЕВСКАЯ,21-А
B17: Страна | D17: РОССИЯ
B18: Лицензия № | F18: =СПЕЦ!C8 -> 10716/291110/10032/11 действует с 08.10.2025 г.
B19: 4 | C19: Место и дата погрузки груза
B20: Место | D20: Суйфэньхэ
B21: Страна | D21: КНР | T21: 18 | U21: Оговорки и замечания перевозчика
B22: Дата | D22: =СМАПП!D20 -> 46025
B23: 5 | C23: Прилагаемые документы | U23: БЕЗ ЗАМЕЧАНИЙ
B24: ="Спецификация № "&СПЕЦ!D1 -> Спецификация № С-RA263-209 | K24: от | L24: =СПЕЦ!C26 -> 46025 | U24: ТОВАРОВ,ЗАПРЕЩЕННЫХ К ВВОЗУ В РФ,НЕТ
B25: ="Инвойс № "&СМАПП!D2 -> Инвойс № CI-20102025-001 | I25: от | J25: =СМАПП!E2 -> 45951
B27: 6 | C27: Знаки и номера | G27: 7 | H27: Количество мест | M27: 8 | N27: Род упаковки | S27: 9 | T27: Наименование груза | X27: 10 | Y27: Статист. № | AB27: 11 | AC27: Вес брутто, кг | AF27: 12 | AG27: Объем, м3
B28: Товары по спецификации № | N28: =СПЕЦ!D1 -> С-RA263-209 | Q28: от | S28: =СПЕЦ!C26 -> 46025 | AB28: =СПЕЦ!L23 -> 1173.6
H30: =СПЕЦ!F23 -> 4 | N30: упаковка по спецификации
B35: Класс | G35: Цифра | L35: Буква | R35: ДОПОГ
B36: 13 | C36: Указания отправителя (таможенная и прочая обработка) | T36: 19 | U36: Подлежит к оплате | X36: Отправитель | AB36: Валюта | AF36: Получатель
A37: Заполняется отправителем 1-15 включая | B37: =СПЕЦ!C7 -> СВХ ООО "НАБАЗ" , ПРИМОРСКИЙ КРАЙ, Г. УССУРИЙСК,УЛ. ЛИМИЧЕВСКАЯ,21-А | T37: Ставка
B38: =СПЕЦ!C8 -> 10716/291110/10032/11 действует с 08.10.2025 г. | T38: Скидки
B39: =СМАПП!D18 -> т/п Уссурийский | T39: Разность
B40: =СМАПП!E18 -> 10716050 | T40: Надбавки
B41: Обявленная стоимость груза | J41: =СПЕЦ!N23 -> 341220 | O41: =ИНВОЙС!E40 -> CNY(кит.юаней) | T41: Допол. сборы
B42: (при превышении предела ответственности предусмотренного гл. IV, ст. 23 п. 3 указывается только после согласованиядополнительной платы к фрахту) | T42: Прочие
T43: Итого к оплате
B44: 14 | C44: Возврат
B45: 15 | C45: Условия оплаты | T45: 20 | U45: Особые согласованные условия
B46: Франко
B47: Нефранко
B48: 21 | C48: Составлена в | G48: =D20 -> Суйфэньхэ | L48: Дата | N48: =СМАПП!D20 -> 46025 | S48: 20 | Z48: 24 | AA48: Груз получен Дата
B49: 22 | C49: Прибытие под погрузку 17 час 30 мин | N49: 23 | O49: Путевой лист № ___ от "____" _______ 20
O50: Фамилии | R50: =СМАПП!D14 -> Шевченко Сергей Дмитриевич | AA50: am "____" ___________ 20___
C51: Убытие 18 час 30 мин | O51: водителей ___________________________ | R51: =СМАПП!D15 -> 77-2950046 | AA51: Прибытие под разгрузку _____ час ____ мин
...

Sheet Данные
A1: Код вида документа. F4 - классификатор | B1: Признак представления документа. F4 - классификатор | C1: Номер документа. F4 - классификатор (для разрешительных документов, контрактов, сертификатов происхождения | D1: Дата документа. F4 - календарь, F9 - сегодня | E1: Наименование документа | F1: Регистрационный номер ДТ/ТД или иного таможенного документа, с которым документ представлялся ранее. F4 - классификатор | G1: Дата начала действия документа. F4 - календарь, F9 - сегодня | H1: Дата окончания действия документа. F4 - календарь, F9 - сегодня | I1: Печать на дополнении (устанавливается автоматически с учетом настроек переноса на дополнение). F9 - указать вручную | T1: Код вида документа. F4 - классификатор | U1: Признак представления документа. F4 - классификатор | V1: Номер документа. F4 - классификатор (для разрешительных документов, контрактов, сертификатов происхождения | W1: Дата документа. F4 - календарь, F9 - сегодня | X1: Наименование документа | Y1: Регистрационный номер ДТ/ТД или иного таможенного документа, с которым документ представлялся ранее. F4 - классификатор | Z1: Дата начала действия документа. F4 - календарь, F9 - сегодня | AA1: Дата окончания действия документа. F4 - календарь, F9 - сегодня | AB1: Печать на дополнении (устанавливается автоматически с учетом настроек переноса на дополнение). F9 - указать вручную
A2: 02015 | B2: 0 | C2: 2090205RA | D2: 02.05.2024 | E2: ТРАНСПОРТНАЯ НАКЛАДНАЯ | I2: НЕОТМЕЧЕНО | T2: 02015 | U2: 0 | V2: =СМАПП!D1 -> RA263-209 | W2: =СМАПП!E1 -> 46025 | X2: ТРАНСПОРТНАЯ НАКЛАДНАЯ
A3: 04021 | B3: 0 | C3: SO/CKIC/2024022701 | D3: 27.02.2024 | E3: СЧЕТ-ФАКТУРА (ИНВОЙС) К ДОГОВОРУ | I3: ОТМЕЧЕНО | T3: 04021 | U3: 0 | V3: =СМАПП!D2 -> CI-20102025-001 | W3: =СМАПП!E2 -> 45951 | X3: СЧЕТ-ФАКТУРА (ИНВОЙС) К ДОГОВОРУ
A4: 04033 | B4: 2 | C4: 2019052101 | D4: 21.05.2019 | E4: ДОГОВОР ПО ПЕРЕВОЗКЕ, ПОГРУЗКЕ, РАЗГРУЗКЕ ИЛИ ПЕРЕГРУЗКЕ ТОВАРОВ | F4: 10228010/270621/0286331 | I4: ОТМЕЧЕНО | T4: 04033 | U4: 2 | V4: 2024050201 | W4: 45409 | X4: ДОГОВОР ПО ПЕРЕВОЗКЕ, ПОГРУЗКЕ, РАЗГРУЗКЕ ИЛИ ПЕРЕГРУЗКЕ ТОВАРОВ | AC4: Интерим-РЭКО
A5: 05999 | B5: 0 | C5: 2090205RA | D5: 02.05.2024 | E5: ОТГРУЗОЧНАЯ СПЕЦИФИКАЦИЯ | I5: ОТМЕЧЕНО | T5: 05999 | U5: 0 | V5: =СПЕЦ!D1 -> С-RA263-209 | W5: =СПЕЦ!C26 -> 46025 | X5: ОТГРУЗОЧНАЯ СПЕЦИФИКАЦИЯ

Sheet доп данные
A1: Условия поставки | D1: Тягач | E1: Прицеп | F1: Вин/рама | G1: Свидетельство о допуске | I1: Водитель ФИО | J1: Паспорт номер | K1: Паспорт дата
A2: / EXW-BEIJING / | D2: Х317КР116 | E2: АМ682725 | F2: ХТС549005G2470345 | I2: Меженьков Владимир Николаевич | J2: 66-8931703 | K2: 45343 | M2: CNY
A3: / DAP-СУЙФЭНЬХЭ / | D3: Е677ТЕ125 | E3: АЕ136525 | F3: XLRTS47MS0G013282 | G3: 10716050-24/2019 | I3: Беззубов Сергей Васильевич | J3: 76-9422616 | K3: 44889 | M3: USD
A4: /FCA-BEIJING/ | D4: В936ВВ125 | E4: АЕ007725 | F4: XLRTE47MS0E939171 | G4: 10716050-33/2019 | H4: 43508 | I4: Шевченко Сергей Дмитриевич | J4: 77-2950046 | K4: 45378 | M4: unit price (¥)
A5: / FCA-СУЙФЭНЬХЭ / | D5: М209АУ125 | E5: АВ994425 | F5: XLRTE47MS0E962123 | G5: 10716050-25/2019 | H5: 43507 | I5: Шевченко Сергей Дмитриевич | J5: 77-2950046 | K5: 45378 | M5: amount (¥)
A6: /CPT- ПОГРАНИЧНЫЙ/ | D6: Т080КХ125 | E6: ОО091125 | F6: XLRTE47MS0G020783 | G6: 10716050-227/2024 | H6: 45462 | I6: Беззубов Сергей Васильевич | J6: 76-9422616 | K6: 44889 | M6: ¥
A7: / EXW-СУЙФЭНЬХЭ / | M7: unit price ($)
A8: /CPT- MOSCOW/ | M8: amount ($)
M9: $
M10: CNY(кит.юаней)
M11: USD(дол.США)

Sheet Получатель и перевозчик
A1: Наименование | B1: Адрес | C1: ИНН | D1: ОГРН | E1: Контракт № | F1: Дата | G1: буквенное наименование для смр | I1: Наименование | J1: Адрес | K1: ИНН | L1: ОГРН
A2: ООО "ИНТЕРИМ" | B2: 690014, Приморский край, г. Владивосток, Народный пр-кт, д.28, офис 318, РФ | C2: ИНН 2543183417 | D2: ОГРН 1242500007958 | E2: INT1704 | F2: 45399 | G2: INT | I2: ИП ПОТКУР МАРИЯ АЛЕКСЕЕВНА | J2: Приморский край, г. Владивосток, ул. Адмирала Юмашева, д.16 Г, кв.70 | K2: ИНН 253150031593 | L2: ОГРНИП 322253600026391
A3: ООО "ДИ ШАН" | B3: 109341, г. Москва, вн.тер.г. муниципальный округ Марьино, ул. Люблинская, д.151, РФ | C3: ИНН 9723178881 | D3: ОГРН 1227700800942 | E3: MSK-DS | F3: 45112 | G3: DS | I3: ООО «РЕАЛ ЭСТЕЙТ КОМПАНИ» | J3: Приморский край, г. Владивосток, ул. Запорожская д.77, оф.720 | K3: ИНН 2538144525 | L3: ОГРН 1112538000706
A4: ООО "МЕЛТ" | B4: 445008, РФ, Самарская область, г. Тольятти, ул. Матросова д.28, кв. 36 | C4: ИНН 6324109545 | D4: ОГРН 1206300018770 | E4: 12/2023 | F4: 45274 | G4: ML
A5: ООО "РЕГИОНАЛЬНАЯ ТОРГОВАЯ КОМПАНИЯ "РОСАКВА" | B5: 197374, г.Санкт-Петербург, вн.тер.г. муниципальный округ № 65, ул. Мебельная, д. 5, литера а, помещ. 1-н | C5: ИНН 7810846669 | D5: ОГРН 1117847475987 | E5: RA-25/2110-CH | F5: 45951 | G5: RA
A6: ООО «ХЭВИ ИНДАСТРИ СОЛЮШНЗ» | B6: 153505, Ивановская обл., м.р-н Ивановский, с.п. Озёрновское, ул.Колхозная, дом 24, РФ | C6: ИНН 3700000812 | D6: ОГРН 1223700010203 | E6: HIS-100125 | F6: 45667 | G6: ХI
A7: ООО "ДЕКРИ ИНЖИНИРИНГ - МОСКВА" | B7: 119421, Г.МОСКВА, ВН.ТЕР.Г. МУНИЦИПАЛЬНЫЙ ОКРУГ ОБРУЧЕВСКИЙ, ПР-КТ ЛЕНИНСКИЙ, Д. 111, К. 1, ПОМЕЩ. 24Н | C7: ИНН 9728100078 | D7: ОГРН 1237700453473 | E7: DK/DKM-4 | F7: 45362 | G7: DIM
A8: ООО «СИБСПЕЦСЕРВИС» | B8: 660055, г. Красноярск, пр. Металлургов 1М строение 2 | C8: ИНН 2465279246 | D8: ОГРН 1122468053366 | E8: 20250807ZJ | F8: 45876 | G8: SS
A9: ООО "АВ КОММЕРС" | B9: 630112, Новосибирская область, г.о. Город Новосибирск, г Новосибирск, ул Красина, здание 54, офис 202 | C9: ИНН 5405010768 | D9: ОГРН 1245400040423 | E9: 10 | F9: 45748 | G9: АВК
A10: ООО «Транслоджистик» | B10: Московская область, г. Москва, ул. Дубининская, дом 67, корпус 2, кабинет 2-13 | C10: ИНН 9701086404 | D10: ОГРН 1177746920427 | E10: TL-DF/1019 | F10: 43740 | G10: TL
A11: ООО "Борей" | B11: 681005, Хабаровский край г. Комсомольск-на-Амуре, ул. Фурманова, 18 лит В, оф 201 | C11: ИНН 2703078170 | D11: ОГРН 1142703001000 | E11: 2506012 | F11: 45859 | G11: BR
A12: ООО "ФАСТ ИМПОРТ" | B12: 117216,г. Москва, УЛ.Феодосийская, д.1, корп. 11, эт.2, офисГ3, РФ | C12: ИНН 7723393317 | D12: ОГРН 1157746488338 | E12: YY2018-30 | F12: 43266 | G12: FI
A13: ООО "Открытая площадка" | B13: 690049, г.о. Владивостокский, г. Владивосток,ул. Бородинская д. 20, офис 203 | C13: ИНН 2543164615 | D13: ОГРН 1222500007531 | E13: DG201024 | F13: 45585 | G13: OP
A14: ООО "ЛИТАС" | B14: 420095, респ. Татарстан, г. Казань, ул. Серова, д. 9А, пом. 17 | C14: ИНН 1658179729 | D14: ОГРН 1151690044043 | E14: LTS20250805 | F14: 45874 | G14: LT
A15: ООО "АТЛАС-М" | B15: 115533, г.Москва, ул. Высокая, Д. 4, КВ. 59 | C15: ИНН 7730707645 | D15: ОГРН 1147746626400 | E15: AM-TJ/2023 | F15: 45209 | G15: АМ
A16: ООО "ВИТА" | B16: 188354, Ленинградсккая обл., Гатчинский м.р-н, Веревско с.п. д.Малое Верево, ул. Кутышева, д. 1,кв. 2 | C16: ИНН 4705095915 | D16: ОГРН 1224700012910 | E16: YH25051 | F16: 45946 | G16: VT

Sheet Отправитель
A1: Наименование компании | B1: Адрес компании
A2: BEIJING DISHANG CLOTHING & ACCESSORIES CO., LTD. | B2: Room 231 Floor 2, Building 19, Ritan North Road, Chaoyang District, City Beijing, China
A3: CHANGZHOU PEI BILLION ENGINEERING MACHINERY CO., LTD. | B3: Province Changzhou city Jiangsu, Zhonglou District,, No.77 Huaide South Road, Xilin Street, China
A4: SHENZHEN RUIQI IMPORT & EXPORT CO., LTD. | B4: Shenzhen, Huangbei Street,Luohu District, C-1203 Southern Building Luofang Road, China
A5: NANTONG OU-LAND INDUSTRY CO.,LTD. | B5: Room 510 No.181 Middle Haiyang Road Rugao City, Jiangsu Prov. China 226500
A6: CHANGSHA KAIYUAN INSTRUMENTS CO., LTD. | B6: No.1259 Liangtang East Road, Changsha Economic&Technological Development Zone Changsha, P. R. China.
A7: WUXI ACHEM VALVE AUTOMATION CO.,LTD. | B7: 214027, Qinglongshan, Wuxi,jiangsu, Building 2,No.129, China
A8: BEIJING DEKREE TRADE DEVELOPMENT CO.,LTD. | B8: 100025, D1501, NO.62 DONG SI HUAN ZHONG LU, CHAOYANG DISTRICT, BEIJING, P.R. CHINA
A9: CHANGZHOU PEI BILLION ENGINEERING MACHINERY CO., LTD | B9: Zhonglou Economic Development Zone, Zhonglou District, Changzhou, Jiangsu No. 39 Guihua Road,
A10: FAST STAR INTERNATIONAL FORWARDING CO., LTD. | B10: Chaoyang district, Baiziwanxili road, bld. 104, unit2, room 212, Beijing, China
A11: MANZHOULI JINFUGUI TRADE CO., LTD | B11: Manzhouli city, Room 8, Block a, Bld 1, Xinhuayuan Community, China
A12: ZHENJIANG JESDA IMPORT AND EXPORT CO., LTD | B12: 2/104 Baota Lane, Zhenjiang City, Jiangsu Pr., China
... A20: YANTAI SUNDY SCIENCE ENVIROMENTAL TECHNOLOGY LTD. | B20: BUILDING 8，NO.39, SCIENCE AND TECHNOLOGY AVENUE, YANTAI HIGH-TECH ZONE, CHINA
